[(Error (py-atom langchain_openai.ChatOpenAI) Exception caught:
RuntimeError: Failed to find "langchain_openai.ChatOpenAI"

At:
  /home/me/.local/lib/python3.10/site-packages/hyperon/stdlib.py(169): find_py_obj
  /home/me/.local/lib/python3.10/site-packages/hyperon/stdlib.py(178): get_py_atom
  /home/me/.local/lib/python3.10/site-packages/hyperon/atoms.py(428): execute
  /home/me/.local/lib/python3.10/site-packages/hyperon/atoms.py(203): _priv_call_execute_on_grounded_atom
  /home/me/.local/lib/python3.10/site-packages/hyperon/runner.py(207): run
  /home/me/.local/lib/python3.10/site-packages/hyperon/metta.py(35): main
  /home/me/.local/bin/metta(8): <module>
)]
real 0.03
user 0.00
sys 0.02
