thread 'main' panicked at repl/src/metta_shim.rs:156:20:
called `Result::unwrap()` on an `Err` value: PyErr { type: <class 'RuntimeError'>, value: RuntimeError('Invalid escape sequence'), traceback: Some(<traceback object at 0x7f6d60f79400>) }
note: run with `RUST_BACKTRACE=1` environment variable to display a backtrace
Command exited with non-zero status 101
0.13user 0.02system 0:00.16elapsed 99%CPU (0avgtext+0avgdata 38304maxresident)k
0inputs+0outputs (0major+4569minor)pagefaults 0swaps
